test_0 (__main__.lab1a.test_0)
[Lab 1] - [Investigation 3] - [Part 2] - printing - Test for file creation: ./lab1a.py ... FAIL

======================================================================
FAIL: test_0 (__main__.lab1a.test_0)
[Lab 1] - [Investigation 3] - [Part 2] - printing - Test for file creation: ./lab1a.py
----------------------------------------------------------------------
Traceback (most recent call last):
  File "/home/fouwhumiakpo/ops445/lab1/./CheckLab1.py", line 60, in test_0
    self.assertTrue(os.path.exists('./lab1a.py'), msg=error_output)
AssertionError: False is not true : your file cannot be found(HINT: make sure you AND your file are in the correct directory)

----------------------------------------------------------------------
Ran 1 test in 0.001s

FAILED (failures=1)
OPS445 Lab Report - System Information for running ./CheckLab1.py
=================================================================
    User login name: fouwhumiakpo
    Git Email: fouwhumiakpo@myseneca.ca
    Linux system name: fouwhumiakpo
    Python executable: /usr/bin/python3
    Python version:  3.12.3 (main, Nov  6 2024, 18:32:19) [GCC 13.2.0]
    OS Platform: linux
    Working Directory: /home/fouwhumiakpo/ops445/lab1
    Start at: Sat May 17 00:03:27 2025
=================================================================
